Traceback (most recent call last):
  File "D:\Users\lr826\AppData\Roaming\Python\Python312\site-packages\jupyter_cache\executors\utils.py", line 58, in single_nb_execution
    executenb(
  File "D:\Users\lr826\AppData\Roaming\Python\Python312\site-packages\nbclient\client.py", line 1314, in execute
    return NotebookClient(nb=nb, resources=resources, km=km, **kwargs).execute()
           ^^^^^^^^^^^^^^^^^^^^^^^^^^^^^^^^^^^^^^^^^^^^^^^^^^^^^^^^^^^^^^^^^^^^^
  File "D:\Users\lr826\AppData\Roaming\Python\Python312\site-packages\jupyter_core\utils\__init__.py", line 165, in wrapped
    return loop.run_until_complete(inner)
           ^^^^^^^^^^^^^^^^^^^^^^^^^^^^^^
  File "D:\Users\lr826\.conda\envs\gee\Lib\asyncio\base_events.py", line 687, in run_until_complete
    return future.result()
           ^^^^^^^^^^^^^^^
  File "D:\Users\lr826\AppData\Roaming\Python\Python312\site-packages\nbclient\client.py", line 709, in async_execute
    await self.async_execute_cell(
  File "D:\Users\lr826\AppData\Roaming\Python\Python312\site-packages\nbclient\client.py", line 1062, in async_execute_cell
    await self._check_raise_for_error(cell, cell_index, exec_reply)
  File "D:\Users\lr826\AppData\Roaming\Python\Python312\site-packages\nbclient\client.py", line 918, in _check_raise_for_error
    raise CellExecutionError.from_cell_and_msg(cell, exec_reply_content)
nbclient.exceptions.CellExecutionError: An error occurred while executing the following cell:
------------------
# AutenticaciÃ³n (solo la primera vez o si vence el token)
ee.Authenticate()
------------------


[1;31m---------------------------------------------------------------------------[0m
[1;31mStdinNotImplementedError[0m                  Traceback (most recent call last)
Cell [1;32mIn[2], line 2[0m
[0;32m      1[0m [38;5;66;03m# AutenticaciÃ³n (solo la primera vez o si vence el token)[39;00m
[1;32m----> 2[0m [43mee[49m[38;5;241;43m.[39;49m[43mAuthenticate[49m[43m([49m[43m)[49m

File [1;32m~\.conda\envs\gee\Lib\site-packages\ee\__init__.py:125[0m, in [0;36mAuthenticate[1;34m(authorization_code, quiet, code_verifier, auth_mode, scopes, force)[0m
[0;32m     94[0m [38;5;28;01mdef[39;00m [38;5;21mAuthenticate[39m(
[0;32m     95[0m     authorization_code: Optional[[38;5;28mstr[39m] [38;5;241m=[39m [38;5;28;01mNone[39;00m,
[0;32m     96[0m     quiet: Optional[[38;5;28mbool[39m] [38;5;241m=[39m [38;5;28;01mNone[39;00m,
[1;32m   (...)[0m
[0;32m    100[0m     force: [38;5;28mbool[39m [38;5;241m=[39m [38;5;28;01mFalse[39;00m,
[0;32m    101[0m ) [38;5;241m-[39m[38;5;241m>[39m Optional[[38;5;28mbool[39m]:
[0;32m    102[0m [38;5;250m  [39m[38;5;124;03m"""Prompts the user to authorize access to Earth Engine via OAuth2.[39;00m
[0;32m    103[0m 
[0;32m    104[0m [38;5;124;03m  Args:[39;00m
[1;32m   (...)[0m
[0;32m    123[0m [38;5;124;03m    True if we found valid credentials and didn't run the auth flow.[39;00m
[0;32m    124[0m [38;5;124;03m  """[39;00m
[1;32m--> 125[0m   [38;5;28;01mreturn[39;00m [43moauth[49m[38;5;241;43m.[39;49m[43mauthenticate[49m[43m([49m[43mauthorization_code[49m[43m,[49m[43m [49m[43mquiet[49m[43m,[49m[43m [49m[43mcode_verifier[49m[43m,[49m[43m [49m[43mauth_mode[49m[43m,[49m
[0;32m    126[0m [43m                            [49m[43mscopes[49m[43m,[49m[43m [49m[43mforce[49m[43m)[49m

File [1;32m~\.conda\envs\gee\Lib\site-packages\ee\oauth.py:521[0m, in [0;36mauthenticate[1;34m(cli_authorization_code, quiet, cli_code_verifier, auth_mode, scopes, force)[0m
[0;32m    518[0m [38;5;28;01mif[39;00m flow[38;5;241m.[39mdisplay_instructions(quiet):
[0;32m    519[0m   _open_new_browser(flow[38;5;241m.[39mauth_url)
[1;32m--> 521[0m [43mflow[49m[38;5;241;43m.[39;49m[43msave_code[49m[43m([49m[43m)[49m

File [1;32m~\.conda\envs\gee\Lib\site-packages\ee\oauth.py:571[0m, in [0;36mFlow.save_code[1;34m(self, code)[0m
[0;32m    569[0m   redirect_uri [38;5;241m=[39m [38;5;28mself[39m[38;5;241m.[39mserver[38;5;241m.[39murl
[0;32m    570[0m   code [38;5;241m=[39m [38;5;28mself[39m[38;5;241m.[39mserver[38;5;241m.[39mfetch_code()  [38;5;66;03m# Waits for oauth callback[39;00m
[1;32m--> 571[0m [43m_obtain_and_write_token[49m[43m([49m[43mcode[49m[43m,[49m[43m [49m[38;5;28;43mself[39;49m[38;5;241;43m.[39;49m[43mcode_verifier[49m[43m,[49m[43m [49m[38;5;28;43mself[39;49m[38;5;241;43m.[39;49m[43mscopes[49m[43m,[49m[43m [49m[43mredirect_uri[49m[43m)[49m

File [1;32m~\.conda\envs\gee\Lib\site-packages\ee\oauth.py:238[0m, in [0;36m_obtain_and_write_token[1;34m(auth_code, code_verifier, scopes, redirect_uri)[0m
[0;32m    236[0m   client_info[[38;5;124m'[39m[38;5;124mredirect_uri[39m[38;5;124m'[39m] [38;5;241m=[39m redirect_uri
[0;32m    237[0m [38;5;28;01mif[39;00m [38;5;129;01mnot[39;00m auth_code:
[1;32m--> 238[0m   auth_code [38;5;241m=[39m [38;5;28;43minput[39;49m[43m([49m[38;5;124;43m'[39;49m[38;5;124;43mEnter verification code: [39;49m[38;5;124;43m'[39;49m[43m)[49m
[0;32m    239[0m [38;5;28;01massert[39;00m [38;5;28misinstance[39m(auth_code, [38;5;28mstr[39m)
[0;32m    240[0m scopes [38;5;241m=[39m scopes [38;5;129;01mor[39;00m SCOPES

File [1;32m~\AppData\Roaming\Python\Python312\site-packages\ipykernel\kernelbase.py:1281[0m, in [0;36mKernel.raw_input[1;34m(self, prompt)[0m
[0;32m   1279[0m [38;5;28;01mif[39;00m [38;5;129;01mnot[39;00m [38;5;28mself[39m[38;5;241m.[39m_allow_stdin:
[0;32m   1280[0m     msg [38;5;241m=[39m [38;5;124m"[39m[38;5;124mraw_input was called, but this frontend does not support input requests.[39m[38;5;124m"[39m
[1;32m-> 1281[0m     [38;5;28;01mraise[39;00m StdinNotImplementedError(msg)
[0;32m   1282[0m [38;5;28;01mreturn[39;00m [38;5;28mself[39m[38;5;241m.[39m_input_request(
[0;32m   1283[0m     [38;5;28mstr[39m(prompt),
[0;32m   1284[0m     [38;5;28mself[39m[38;5;241m.[39m_parent_ident[[38;5;124m"[39m[38;5;124mshell[39m[38;5;124m"[39m],
[0;32m   1285[0m     [38;5;28mself[39m[38;5;241m.[39mget_parent([38;5;124m"[39m[38;5;124mshell[39m[38;5;124m"[39m),
[0;32m   1286[0m     password[38;5;241m=[39m[38;5;28;01mFalse[39;00m,
[0;32m   1287[0m )

[1;31mStdinNotImplementedError[0m: raw_input was called, but this frontend does not support input requests.

