Traceback (most recent call last):
  File "D:\Users\lr826\AppData\Roaming\Python\Python312\site-packages\jupyter_cache\executors\utils.py", line 58, in single_nb_execution
    executenb(
  File "D:\Users\lr826\AppData\Roaming\Python\Python312\site-packages\nbclient\client.py", line 1314, in execute
    return NotebookClient(nb=nb, resources=resources, km=km, **kwargs).execute()
           ^^^^^^^^^^^^^^^^^^^^^^^^^^^^^^^^^^^^^^^^^^^^^^^^^^^^^^^^^^^^^^^^^^^^^
  File "D:\Users\lr826\AppData\Roaming\Python\Python312\site-packages\jupyter_core\utils\__init__.py", line 165, in wrapped
    return loop.run_until_complete(inner)
           ^^^^^^^^^^^^^^^^^^^^^^^^^^^^^^
  File "D:\Users\lr826\.conda\envs\gee\Lib\asyncio\base_events.py", line 687, in run_until_complete
    return future.result()
           ^^^^^^^^^^^^^^^
  File "D:\Users\lr826\AppData\Roaming\Python\Python312\site-packages\nbclient\client.py", line 709, in async_execute
    await self.async_execute_cell(
  File "D:\Users\lr826\AppData\Roaming\Python\Python312\site-packages\nbclient\client.py", line 1062, in async_execute_cell
    await self._check_raise_for_error(cell, cell_index, exec_reply)
  File "D:\Users\lr826\AppData\Roaming\Python\Python312\site-packages\nbclient\client.py", line 918, in _check_raise_for_error
    raise CellExecutionError.from_cell_and_msg(cell, exec_reply_content)
nbclient.exceptions.CellExecutionError: An error occurred while executing the following cell:
------------------
ee.Initialize(project='ee-luisreynoso')
------------------


[1;31m---------------------------------------------------------------------------[0m
[1;31mEEException[0m                               Traceback (most recent call last)
Cell [1;32mIn[3], line 1[0m
[1;32m----> 1[0m [43mee[49m[38;5;241;43m.[39;49m[43mInitialize[49m[43m([49m[43mproject[49m[38;5;241;43m=[39;49m[38;5;124;43m'[39;49m[38;5;124;43mee-luisreynoso[39;49m[38;5;124;43m'[39;49m[43m)[49m

File [1;32m~\.conda\envs\gee\Lib\site-packages\ee\_utils.py:38[0m, in [0;36maccept_opt_prefix.<locals>.opt_fixed.<locals>.wrapper[1;34m(*args, **kwargs)[0m
[0;32m     36[0m     [38;5;28;01mif[39;00m new_key [38;5;129;01mnot[39;00m [38;5;129;01min[39;00m kwargs:
[0;32m     37[0m       kwargs[new_key] [38;5;241m=[39m old_key_val
[1;32m---> 38[0m [38;5;28;01mreturn[39;00m [43mfunc[49m[43m([49m[38;5;241;43m*[39;49m[43margs[49m[43m,[49m[43m [49m[38;5;241;43m*[39;49m[38;5;241;43m*[39;49m[43mkwargs[49m[43m)[49m

File [1;32m~\.conda\envs\gee\Lib\site-packages\ee\__init__.py:154[0m, in [0;36mInitialize[1;34m(credentials, url, cloud_api_key, http_transport, project)[0m
[0;32m    137[0m [38;5;250m[39m[38;5;124;03m"""Initialize the EE library.[39;00m
[0;32m    138[0m 
[0;32m    139[0m [38;5;124;03mIf this hasn't been called by the time any object constructor is used,[39;00m
[1;32m   (...)[0m
[0;32m    151[0m [38;5;124;03m  project: The client project ID or number to use when making API calls.[39;00m
[0;32m    152[0m [38;5;124;03m"""[39;00m
[0;32m    153[0m [38;5;28;01mif[39;00m credentials [38;5;241m==[39m [38;5;124m'[39m[38;5;124mpersistent[39m[38;5;124m'[39m:
[1;32m--> 154[0m   credentials [38;5;241m=[39m [43mdata[49m[38;5;241;43m.[39;49m[43mget_persistent_credentials[49m[43m([49m[43m)[49m
[0;32m    155[0m [38;5;28;01mif[39;00m [38;5;129;01mnot[39;00m project [38;5;129;01mand[39;00m credentials [38;5;129;01mand[39;00m [38;5;28mhasattr[39m(credentials, [38;5;124m'[39m[38;5;124mquota_project_id[39m[38;5;124m'[39m):
[0;32m    156[0m   project [38;5;241m=[39m credentials[38;5;241m.[39mquota_project_id

File [1;32m~\.conda\envs\gee\Lib\site-packages\ee\data.py:281[0m, in [0;36mget_persistent_credentials[1;34m()[0m
[0;32m    279[0m   [38;5;28;01mif[39;00m oauth[38;5;241m.[39mis_valid_credentials(credentials):
[0;32m    280[0m     [38;5;28;01mreturn[39;00m credentials
[1;32m--> 281[0m [38;5;28;01mraise[39;00m ee_exception[38;5;241m.[39mEEException(  [38;5;66;03m# pylint: disable=raise-missing-from[39;00m
[0;32m    282[0m     [38;5;124m'[39m[38;5;124mPlease authorize access to your Earth Engine account by [39m[38;5;124m'[39m
[0;32m    283[0m     [38;5;124m'[39m[38;5;124mrunning[39m[38;5;130;01m\n[39;00m[38;5;130;01m\n[39;00m[38;5;124mearthengine authenticate[39m[38;5;130;01m\n[39;00m[38;5;130;01m\n[39;00m[38;5;124m'[39m
[0;32m    284[0m     [38;5;124m'[39m[38;5;124min your command line, or ee.Authenticate() in Python, and then retry.[39m[38;5;124m'[39m
[0;32m    285[0m )

[1;31mEEException[0m: Please authorize access to your Earth Engine account by running

earthengine authenticate

in your command line, or ee.Authenticate() in Python, and then retry.

